Workbook
Name Classical: Genres!$K$2:$K$1048576
Name Country: Genres!$L$2:$L$1048576
Name Electronic: Genres!$M$2:$M$1048576
Name Hip_Hop: Genres!$N$2:$N$1048576
Name International: Genres!$O$2:$O$1048576
Name Jazz: Genres!$P$2:$P$1048576
Name Metal: Genres!$Q$2:$Q$1048576
Name Other: Genres!$V$2:$V$1048576
Name Parent_Genre: Genres!$J$2:$J$1048576
Name Pop: Genres!$R$2:$R$1048576
Name R_B: Genres!$S$2:$S$1048576
Name Rap: Genres!$T$2:$T$1048576
Name Rock: Genres!$U$2:$U$1048576

Sheet Da Rules
A1: The Consitution of MPE Moosic
A5: Bill of Rights | G5: Rules
A6: 1 | B6: Right to vote | G6: 1 | H6: The user shall post a song every work day
A7: 2 | B7: Right to post any song | G7: 2 | H7: The user shall vote for the previous day before posting
A8: 3 | G8: 3 | H8: The user shall listen to each song until the song ends or for at least 6 minutes, whichever comes first
A9: 4 | G9: 4 | H9: The user shall be truthful with the votes
A10: 5 | G10: 5 | H10: The user shall not repeat a song
A11: 6 | G11: 6 | H11: The user shall announce the theme by Tuesday COB
A12: 7 | G12: 7 | H12: The user shall vote for the theme by noon on Wednesday
A13: 8 | G13: 8 | H13: Non-Proliferation Treaty
A14: 9 | G14: 9
A15: 10 | G15: 10
A16: Amendments | G16: Proposed Rules | M16: Joe | N16: Daniel | O16: Heran | P16: Sam | Q16: Logan
A17: 1 | B17: Right to veto a theme | G17: 1 | H17: The user shall vote each day by 3pm unless otherwise planned. | M17: N | N17: Y | O17: Y | P17: Y | Q17: y
A18: 2 | G18: 2 | H18: If a user doesn't submit a vote within 2 business days, their votes shall be determined by an RNG | N18: y
A19: 3 | G19: 3 | H19: A user can change their song entry as long as there are less than 3 songs posted for the day. | M19: Y | N19: Y | O19: Y | Q19: Y
A20: 4 | G20: 4 | H20: If a user doesn't submit their votes within 3 business days, they have to give themselves a 5 for that day. | M20: N | N20: Y | O20: Y | P20: Y | Q20: Y
A21: 5 | G21: 5
A22: 6 | G22: 6
A23: 7 | G23: 7
A24: 8 | G24: 8
A25: 9 | G25: 9
A26: 10 | G26: 10
A27: 11 | G27: 11
A28: 12 | G28: 12
A29: 13 | G29: 13
A30: 14 | G30: 14
A31: 15 | G31: 15
G32: If rules have been proposed, votes will be cast in this document. If the rule was proposed before noon, a vote will be held and a ruling will be made by the end of the same work day. Otherwise, a vote and ruling will be held the following work day. A unanimous vote is needed to pass.

Sheet Rankings
A1: Date | B1: Cover Art | C1: Winner of the day | D1: Date | E1: Poster | F1: Average | G1: STDEV | H1: Song Title | I1: Artist | J1: alappatjoe | K1: danram | L1: loganworsdell | M1: samuelbattista | N1: currydestroyer27 | O1: Plays | P1: Parent Genre | Q1: Sub-Genre | R1: Day Rank | S1: W Rank | T1: Winner | U1: Notes
A2: 45455 | C2: {=_xlfn.LET(_xlpm.matches, _xlfn._xlws.FILTER(Data[Poster], (Data[Date]=A2)*(Data[Winner]=TRUE)), IF(ROWS(_xlpm.matches)>1, "TIE", _xlpm.matches))} -> danram | D2: =A2 -> 45455 | E2: =$J$1 -> alappatjoe | F2: =IFERROR(AVERAGE(Data[[#This Row],[alappatjoe]:[currydestroyer27]]), "TBD") -> 2.8 | G2: =IFERROR(_xlfn.STDEV.P(Data[[#This Row],[alappatjoe]:[currydestroyer27]]), "TBD") -> 1.3266499 | H2: Training Season | I2: Dua Lipa | J2: 1 | K2: 5 | L2: 3 | M2: 2 | N2: 3 | P2: Pop | Q2: Dance Pop | R2: =IF(SUM(Data[[#This Row],[alappatjoe]:[currydestroyer27]])>0, COUNTIFS(Data[Date], Data[[#This Row],[Date]], Data[Average], "<"&Data[[#This Row],[Average]]) + COUNTIFS(Data[Date], Data[[#This Row],[Date]], Data[Average], Data[[#This Row],[Average]], Data[STDEV], "<"&Data[[#This Row],[STDEV]])+1, "TBD") -> 2 | S2: 1 | T2: =Data[[#This Row],[Day Rank]]=Data[[#This Row],[W Rank]] -> FALSE
D3: =D2 -> 45455 | E3: =$K$1 -> danram | F3: =IFERROR(AVERAGE(Data[[#This Row],[alappatjoe]:[currydestroyer27]]), "TBD") -> 2.2 | G3: =IFERROR(_xlfn.STDEV.P(Data[[#This Row],[alappatjoe]:[currydestroyer27]]), "TBD") -> 0.74833148 | H3: Mosquito | I3: PinkPantheress | J3: 3 | K3: 1 | L3: 2 | M3: 3 | N3: 2 | P3: Pop | Q3: UK Garage | R3: =IF(SUM(Data[[#This Row],[alappatjoe]:[currydestroyer27]])>0, COUNTIFS(Data[Date], Data[[#This Row],[Date]], Data[Average], "<"&Data[[#This Row],[Average]]) + COUNTIFS(Data[Date], Data[[#This Row],[Date]], Data[Average], Data[[#This Row],[Average]], Data[STDEV], "<"&Data[[#This Row],[STDEV]])+1, "TBD") -> 1 | S3: 1 | T3: =Data[[#This Row],[Day Rank]]=Data[[#This Row],[W Rank]] -> TRUE
D4: =D2 -> 45455 | E4: =$L$1 -> loganworsdell | F4: =IFERROR(AVERAGE(Data[[#This Row],[alappatjoe]:[currydestroyer27]]), "TBD") -> 3.2 | G4: =IFERROR(_xlfn.STDEV.P(Data[[#This Row],[alappatjoe]:[currydestroyer27]]), "TBD") -> 1.1661904 | H4: Earthquake | I4: Ferdous | J4: 4 | K4: 3 | L4: 1 | M4: 4 | N4: 4 | P4: Electronic | Q4: Dance/Electronic | R4: =IF(SUM(Data[[#This Row],[alappatjoe]:[currydestroyer27]])>0, COUNTIFS(Data[Date], Data[[#This Row],[Date]], Data[Average], "<"&Data[[#This Row],[Average]]) + COUNTIFS(Data[Date], Data[[#This Row],[Date]], Data[Average], Data[[#This Row],[Average]], Data[STDEV], "<"&Data[[#This Row],[STDEV]])+1, "TBD") -> 4 | S4: 1 | T4: =Data[[#This Row],[Day Rank]]=Data[[#This Row],[W Rank]] -> FALSE
D5: =D2 -> 45455 | E5: =$M$1 -> samuelbattista | F5: =IFERROR(AVERAGE(Data[[#This Row],[alappatjoe]:[currydestroyer27]]), "TBD") -> 2.8 | G5: =IFERROR(_xlfn.STDEV.P(Data[[#This Row],[alappatjoe]:[currydestroyer27]]), "TBD") -> 1.4696938 | H5: No Problems | I5: Ginger Root | J5: 2 | K5: 2 | L5: 4 | M5: 1 | N5: 5 | P5: Pop | Q5: Indie Pop | R5: =IF(SUM(Data[[#This Row],[alappatjoe]:[currydestroyer27]])>0, COUNTIFS(Data[Date], Data[[#This Row],[Date]], Data[Average], "<"&Data[[#This Row],[Average]]) + COUNTIFS(Data[Date], Data[[#This Row],[Date]], Data[Average], Data[[#This Row],[Average]], Data[STDEV], "<"&Data[[#This Row],[STDEV]])+1, "TBD") -> 3 | S5: 1 | T5: =Data[[#This Row],[Day Rank]]=Data[[#This Row],[W Rank]] -> FALSE
D6: =D2 -> 45455 | E6: =$N$1 -> currydestroyer27 | F6: =IFERROR(AVERAGE(Data[[#This Row],[alappatjoe]:[currydestroyer27]]), "TBD") -> 4 | G6: =IFERROR(_xlfn.STDEV.P(Data[[#This Row],[alappatjoe]:[currydestroyer27]]), "TBD") -> 1.5491933 | H6: Fly Away | I6: TheFatRat, Anjulie | J6: 5 | K6: 4 | L6: 5 | M6: 5 | N6: 1 | P6: Electronic | Q6: EDM | R6: =IF(SUM(Data[[#This Row],[alappatjoe]:[currydestroyer27]])>0, COUNTIFS(Data[Date], Data[[#This Row],[Date]], Data[Average], "<"&Data[[#This Row],[Average]]) + COUNTIFS(Data[Date], Data[[#This Row],[Date]], Data[Average], Data[[#This Row],[Average]], Data[STDEV], "<"&Data[[#This Row],[STDEV]])+1, "TBD") -> 5 | S6: 1 | T6: =Data[[#This Row],[Day Rank]]=Data[[#This Row],[W Rank]] -> FALSE
A7: 45456 | C7: {=_xlfn.LET(_xlpm.matches, _xlfn._xlws.FILTER(Data[Poster], (Data[Date]=A7)*(Data[Winner]=TRUE)), IF(ROWS(_xlpm.matches)>1, "TIE", _xlpm.matches))} -> alappatjoe | D7: =A7 -> 45456 | E7: =$J$1 -> alappatjoe | F7: =IFERROR(AVERAGE(Data[[#This Row],[alappatjoe]:[currydestroyer27]]), "TBD") -> 2.2 | G7: =IFERROR(_xlfn.STDEV.P(Data[[#This Row],[alappatjoe]:[currydestroyer27]]), "TBD") -> 0.74833148 | H7: Illusion - Extended | I7: Dua Lipa | J7: 1 | K7: 2 | L7: 2 | M7: 3 | N7: 3 | P7: Pop | Q7: Dance Pop | R7: =IF(SUM(Data[[#This Row],[alappatjoe]:[currydestroyer27]])>0, COUNTIFS(Data[Date], Data[[#This Row],[Date]], Data[Average], "<"&Data[[#This Row],[Average]]) + COUNTIFS(Data[Date], Data[[#This Row],[Date]], Data[Average], Data[[#This Row],[Average]], Data[STDEV], "<"&Data[[#This Row],[STDEV]])+1, "TBD") -> 1 | S7: 1 | T7: =Data[[#This Row],[Day Rank]]=Data[[#This Row],[W Rank]] -> TRUE
D8: =D7 -> 45456 | E8: =$K$1 -> danram | F8: =IFERROR(AVERAGE(Data[[#This Row],[alappatjoe]:[currydestroyer27]]), "TBD") -> 4.6 | G8: =IFERROR(_xlfn.STDEV.P(Data[[#This Row],[alappatjoe]:[currydestroyer27]]), "TBD") -> 0.8 | H8: Took Em Down | I8: BredGawd, LAZER DIM 700 | J8: 5 | K8: 3 | L8: 5 | M8: 5 | N8: 5 | P8: Rap | Q8: Rap | R8: =IF(SUM(Data[[#This Row],[alappatjoe]:[currydestroyer27]])>0, COUNTIFS(Data[Date], Data[[#This Row],[Date]], Data[Average], "<"&Data[[#This Row],[Average]]) + COUNTIFS(Data[Date], Data[[#This Row],[Date]], Data[Average], Data[[#This Row],[Average]], Data[STDEV], "<"&Data[[#This Row],[STDEV]])+1, "TBD") -> 5 | S8: 1 | T8: =Data[[#This Row],[Day Rank]]=Data[[#This Row],[W Rank]] -> FALSE
D9: =D7 -> 45456 | E9: =$L$1 -> loganworsdell | F9: =IFERROR(AVERAGE(Data[[#This Row],[alappatjoe]:[currydestroyer27]]), "TBD") -> 2.2 | G9: =IFERROR(_xlfn.STDEV.P(Data[[#This Row],[alappatjoe]:[currydestroyer27]]), "TBD") -> 1.4696938 | H9: Top 10 staTues tHat CriEd bloOd | I9: Bring Me The Horizon | J9: 4 | K9: 1 | L9: 1 | M9: 1 | N9: 4 | P9: Metal | Q9: Metalcore | R9: =IF(SUM(Data[[#This Row],[alappatjoe]:[currydestroyer27]])>0, COUNTIFS(Data[Date], Data[[#This Row],[Date]], Data[Average], "<"&Data[[#This Row],[Average]]) + COUNTIFS(Data[Date], Data[[#This Row],[Date]], Data[Average], Data[[#This Row],[Average]], Data[STDEV], "<"&Data[[#This Row],[STDEV]])+1, "TBD") -> 2 | S9: 1 | T9: =Data[[#This Row],[Day Rank]]=Data[[#This Row],[W Rank]] -> FALSE
D10: =D7 -> 45456 | E10: =$M$1 -> samuelbattista | F10: =IFERROR(AVERAGE(Data[[#This Row],[alappatjoe]:[currydestroyer27]]), "TBD") -> 2.6 | G10: =IFERROR(_xlfn.STDEV.P(Data[[#This Row],[alappatjoe]:[currydestroyer27]]), "TBD") -> 1.0198039 | H10: RATATATA | I10: BABYMETAL, Electric Callboy | J10: 3 | K10: 4 | L10: 3 | M10: 2 | N10: 1 | P10: International | Q10: J-Metal | R10: =IF(SUM(Data[[#This Row],[alappatjoe]:[currydestroyer27]])>0, COUNTIFS(Data[Date], Data[[#This Row],[Date]], Data[Average], "<"&Data[[#This Row],[Average]]) + COUNTIFS(Data[Date], Data[[#This Row],[Date]], Data[Average], Data[[#This Row],[Average]], Data[STDEV], "<"&Data[[#This Row],[STDEV]])+1, "TBD") -> 3 | S10: 1 | T10: =Data[[#This Row],[Day Rank]]=Data[[#This Row],[W Rank]] -> FALSE
D11: =D7 -> 45456 | E11: =$N$1 -> currydestroyer27 | F11: =IFERROR(AVERAGE(Data[[#This Row],[alappatjoe]:[currydestroyer27]]), "TBD") -> 3.4 | G11: =IFERROR(_xlfn.STDEV.P(Data[[#This Row],[alappatjoe]:[currydestroyer27]]), "TBD") -> 1.2 | H11: Blue Skies - Revoke Remix | I11: Lenka, REVOKE | J11: 2 | K11: 5 | L11: 4 | M11: 4 | N11: 2 | P11: Pop | Q11: Alternative Pop | R11: =IF(SUM(Data[[#This Row],[alappatjoe]:[currydestroyer27]])>0, COUNTIFS(Data[Date], Data[[#This Row],[Date]], Data[Average], "<"&Data[[#This Row],[Average]]) + COUNTIFS(Data[Date], Data[[#This Row],[Date]], Data[Average], Data[[#This Row],[Average]], Data[STDEV], "<"&Data[[#This Row],[STDEV]])+1, "TBD") -> 4 | S11: 1 | T11: =Data[[#This Row],[Day Rank]]=Data[[#This Row],[W Rank]] -> FALSE
A12: 45460 | C12: {=_xlfn.LET(_xlpm.matches, _xlfn._xlws.FILTER(Data[Poster], (Data[Date]=A12)*(Data[Winner]=TRUE)), IF(ROWS(_xlpm.matches)>1, "TIE", _xlpm.matches))} -> danram | D12: =A12 -> 45460 | E12: =$J$1 -> alappatjoe | F12: =IFERROR(AVERAGE(Data[[#This Row],[alappatjoe]:[currydestroyer27]]), "TBD") -> 4 | G12: =IFERROR(_xlfn.STDEV.P(Data[[#This Row],[alappatjoe]:[currydestroyer27]]), "TBD") -> 1.2649111 | H12: Not My Fault | I12: Renee Rapp, Megan Thee Stallion | J12: 2 | K12: 5 | L12: 5 | M12: 5 | N12: 3 | P12: Pop | Q12: Pop | R12: =IF(SUM(Data[[#This Row],[alappatjoe]:[currydestroyer27]])>0, COUNTIFS(Data[Date], Data[[#This Row],[Date]], Data[Average], "<"&Data[[#This Row],[Average]]) + COUNTIFS(Data[Date], Data[[#This Row],[Date]], Data[Average], Data[[#This Row],[Average]], Data[STDEV], "<"&Data[[#This Row],[STDEV]])+1, "TBD") -> 5 | S12: 1 | T12: =Data[[#This Row],[Day Rank]]=Data[[#This Row],[W Rank]] -> FALSE
D13: =D12 -> 45460 | E13: =$K$1 -> danram | F13: =IFERROR(AVERAGE(Data[[#This Row],[alappatjoe]:[currydestroyer27]]), "TBD") -> 2.2 | G13: =IFERROR(_xlfn.STDEV.P(Data[[#This Row],[alappatjoe]:[currydestroyer27]]), "TBD") -> 0.9797959 | H13: BIRDS OF A FEATHER | I13: Billie Eilish | J13: 1 | K13: 2 | L13: 4 | M13: 2 | N13: 2 | P13: Pop | Q13: Alternative Pop | R13: =IF(SUM(Data[[#This Row],[alappatjoe]:[currydestroyer27]])>0, COUNTIFS(Data[Date], Data[[#This Row],[Date]], Data[Average], "<"&Data[[#This Row],[Average]]) + COUNTIFS(Data[Date], Data[[#This Row],[Date]], Data[Average], Data[[#This Row],[Average]], Data[STDEV], "<"&Data[[#This Row],[STDEV]])+1, "TBD") -> 1 | S13: 1 | T13: =Data[[#This Row],[Day Rank]]=Data[[#This Row],[W Rank]] -> TRUE
D14: =D12 -> 45460 | E14: =$L$1 -> loganworsdell | F14: =IFERROR(AVERAGE(Data[[#This Row],[alappatjoe]:[currydestroyer27]]), "TBD") -> 3.4 | G14: =IFERROR(_xlfn.STDEV.P(Data[[#This Row],[alappatjoe]:[currydestroyer27]]), "TBD") -> 1.0198039 | H14: 2000 chevy malibu | I14: Channel Tres | J14: 3 | K14: 4 | L14: 2 | M14: 3 | N14: 5 | P14: R&B | Q14: Indie soul | R14: =IF(SUM(Data[[#This Row],[alappatjoe]:[currydestroyer27]])>0, COUNTIFS(Data[Date], Data[[#This Row],[Date]], Data[Average], "<"&Data[[#This Row],[Average]]) + COUNTIFS(Data[Date], Data[[#This Row],[Date]], Data[Average], Data[[#This Row],[Average]], Data[STDEV], "<"&Data[[#This Row],[STDEV]])+1, "TBD") -> 4 | S14: 1 | T14: =Data[[#This Row],[Day Rank]]=Data[[#This Row],[W Rank]] -> FALSE
D15: =D12 -> 45460 | E15: =$M$1 -> samuelbattista | F15: =IFERROR(AVERAGE(Data[[#This Row],[alappatjoe]:[currydestroyer27]]), "TBD") -> 2.6 | G15: =IFERROR(_xlfn.STDEV.P(Data[[#This Row],[alappatjoe]:[currydestroyer27]]), "TBD") -> 1.356466 | H15: Hollywood Baby | I15: 100 gecs | J15: 4 | K15: 1 | L15: 3 | M15: 1 | N15: 4 | P15: Pop | Q15: Hyperpop | R15: =IF(SUM(Data[[#This Row],[alappatjoe]:[currydestroyer27]])>0, COUNTIFS(Data[Date], Data[[#This Row],[Date]], Data[Average], "<"&Data[[#This Row],[Average]]) + COUNTIFS(Data[Date], Data[[#This Row],[Date]], Data[Average], Data[[#This Row],[Average]], Data[STDEV], "<"&Data[[#This Row],[STDEV]])+1, "TBD") -> 2 | S15: 1 | T15: =Data[[#This Row],[Day Rank]]=Data[[#This Row],[W Rank]] -> FALSE
D16: =D12 -> 45460 | E16: =$N$1 -> currydestroyer27 | F16: =IFERROR(AVERAGE(Data[[#This Row],[alappatjoe]:[currydestroyer27]]), "TBD") -> 2.8 | G16: =IFERROR(_xlfn.STDEV.P(Data[[#This Row],[alappatjoe]:[currydestroyer27]]), "TBD") -> 1.6 | H16: Bandit | I16: Don Toliver | J16: 5 | K16: 3 | L16: 1 | M16: 4 | N16: 1 | P16: Rap | Q16: Rap | R16: =IF(SUM(Data[[#This Row],[alappatjoe]:[currydestroyer27]])>0, COUNTIFS(Data[Date], Data[[#This Row],[Date]], Data[Average], "<"&Data[[#This Row],[Average]]) + COUNTIFS(Data[Date], Data[[#This Row],[Date]], Data[Average], Data[[#This Row],[Average]], Data[STDEV], "<"&Data[[#This Row],[STDEV]])+1, "TBD") -> 3 | S16: 1 | T16: =Data[[#This Row],[Day Rank]]=Data[[#This Row],[W Rank]] -> FALSE
A17: 45461 | C17: {=_xlfn.LET(_xlpm.matches, _xlfn._xlws.FILTER(Data[Poster], (Data[Date]=A17)*(Data[Winner]=TRUE)), IF(ROWS(_xlpm.matches)>1, "TIE", _xlpm.matches))} -> loganworsdell | D17: =A17 -> 45461 | E17: =$J$1 -> alappatjoe | F17: =IFERROR(AVERAGE(Data[[#This Row],[alappatjoe]:[currydestroyer27]]), "TBD") -> 3.4 | G17: =IFERROR(_xlfn.STDEV.P(Data[[#This Row],[alappatjoe]:[currydestroyer27]]), "TBD") -> 0.8 | H17: Standing Next to You | I17: Jung Kook | J17: 2 | K17: 4 | L17: 4 | M17: 4 | N17: 3 | P17: International | Q17: K-Pop | R17: =IF(SUM(Data[[#This Row],[alappatjoe]:[currydestroyer27]])>0, COUNTIFS(Data[Date], Data[[#This Row],[Date]], Data[Average], "<"&Data[[#This Row],[Average]]) + COUNTIFS(Data[Date], Data[[#This Row],[Date]], Data[Average], Data[[#This Row],[Average]], Data[STDEV], "<"&Data[[#This Row],[STDEV]])+1, "TBD") -> 4 | S17: 1 | T17: =Data[[#This Row],[Day Rank]]=Data[[#This Row],[W Rank]] -> FALSE
D18: =D17 -> 45461 | E18: =$K$1 -> danram | F18: =IFERROR(AVERAGE(Data[[#This Row],[alappatjoe]:[currydestroyer27]]), "TBD") -> 3.2 | G18: =IFERROR(_xlfn.STDEV.P(Data[[#This Row],[alappatjoe]:[currydestroyer27]]), "TBD") -> 0.9797959 | H18: Lonely Rolling Star | I18: Katamari Soundtrack | J18: 5 | K18: 3 | L18: 3 | M18: 3 | N18: 2 | P18: International | Q18: J-Pop | R18: =IF(SUM(Data[[#This Row],[alappatjoe]:[currydestroyer27]])>0, COUNTIFS(Data[Date], Data[[#This Row],[Date]], Data[Average], "<"&Data[[#This Row],[Average]]) + COUNTIFS(Data[Date], Data[[#This Row],[Date]], Data[Average], Data[[#This Row],[Average]], Data[STDEV], "<"&Data[[#This Row],[STDEV]])+1, "TBD") -> 3 | S18: 1 | T18: =Data[[#This Row],[Day Rank]]=Data[[#This Row],[W Rank]] -> FALSE
D19: =D17 -> 45461 | E19: =$L$1 -> loganworsdell | F19: =IFERROR(AVERAGE(Data[[#This Row],[alappatjoe]:[currydestroyer27]]), "TBD") -> 1.8 | G19: =IFERROR(_xlfn.STDEV.P(Data[[#This Row],[alappatjoe]:[currydestroyer27]]), "TBD") -> 0.74833148 | H19: Candle Flame | I19: Jungle, Erick the Architect | J19: 3 | K19: 1 | L19: 2 | M19: 2 | N19: 1 | P19: R&B | Q19: UK Contemporary R&B | R19: =IF(SUM(Data[[#This Row],[alappatjoe]:[currydestroyer27]])>0, COUNTIFS(Data[Date], Data[[#This Row],[Date]], Data[Average], "<"&Data[[#This Row],[Average]]) + COUNTIFS(Data[Date], Data[[#This Row],[Date]], Data[Average], Data[[#This Row],[Average]], Data[STDEV], "<"&Data[[#This Row],[STDEV]])+1, "TBD") -> 1 | S19: 1 | T19: =Data[[#This Row],[Day Rank]]=Data[[#This Row],[W Rank]] -> TRUE
D20: =D17 -> 45461 | E20: =$M$1 -> samuelbattista | F20: =IFERROR(AVERAGE(Data[[#This Row],[alappatjoe]:[currydestroyer27]]), "TBD") -> 2 | G20: =IFERROR(_xlfn.STDEV.P(Data[[#This Row],[alappatjoe]:[currydestroyer27]]), "TBD") -> 1.5491933 | H20: Fly as Me | I20: Silk Sonic | J20: 1 | K20: 2 | L20: 1 | M20: 1 | N20: 5 | P20: R&B | Q20: Neo Soul | R20: =IF(SUM(Data[[#This Row],[alappatjoe]:[currydestroyer27]])>0, COUNTIFS(Data[Date], Data[[#This Row],[Date]], Data[Average], "<"&Data[[#This Row],[Average]]) + COUNTIFS(Data[Date], Data[[#This Row],[Date]], Data[Average], Data[[#This Row],[Average]], Data[STDEV], "<"&Data[[#This Row],[STDEV]])+1, "TBD") -> 2 | S20: 1 | T20: =Data[[#This Row],[Day Rank]]=Data[[#This Row],[W Rank]] -> FALSE
D21: =D17 -> 45461 | E21: =$N$1 -> currydestroyer27 | F21: =IFERROR(AVERAGE(Data[[#This Row],[alappatjoe]:[currydestroyer27]]), "TBD") -> 4.6 | G21: =IFERROR(_xlfn.STDEV.P(Data[[#This Row],[alappatjoe]:[currydestroyer27]]), "TBD") -> 0.48989795 | H21: Ill Mind of Hopsin 8 | I21: Hopsin | J21: 4 | K21: 5 | L21: 5 | M21: 5 | N21: 4 | P21: Rap | Q21: Rap | R21: =IF(SUM(Data[[#This Row],[alappatjoe]:[currydestroyer27]])>0, COUNTIFS(Data[Date], Data[[#This Row],[Date]], Data[Average], "<"&Data[[#This Row],[Average]]) + COUNTIFS(Data[Date], Data[[#This Row],[Date]], Data[Average], Data[[#This Row],[Average]], Data[STDEV], "<"&Data[[#This Row],[STDEV]])+1, "TBD") -> 5 | S21: 1 | T21: =Data[[#This Row],[Day Rank]]=Data[[#This Row],[W Rank]] -> FALSE
A22: 45462 | C22: {=_xlfn.LET(_xlpm.matches, _xlfn._xlws.FILTER(Data[Poster], (Data[Date]=A22)*(Data[Winner]=TRUE)), IF(ROWS(_xlpm.matches)>1, "TIE", _xlpm.matches))} -> currydestroyer27 | D22: =A22 -> 45462 | E22: =$J$1 -> alappatjoe | F22: =IFERROR(AVERAGE(Data[[#This Row],[alappatjoe]:[currydestroyer27]]), "TBD") -> 3 | G22: =IFERROR(_xlfn.STDEV.P(Data[[#This Row],[alappatjoe]:[currydestroyer27]]), "TBD") -> 1.4142136 | H22: ラブ・ドラマティック (Funky Flag Version) | I22: Masayuki Suzuki, Rikka Ihara | J22: 1 | K22: 5 | L22: 2 | M22: 4 | N22: 3 | P22: International | Q22: J-Pop | R22: =IF(SUM(Data[[#This Row],[alappatjoe]:[currydestroyer27]])>0, COUNTIFS(Data[Date], Data[[#This Row],[Date]], Data[Average], "<"&Data[[#This Row],[Average]]) + COUNTIFS(Data[Date], Data[[#This Row],[Date]], Data[Average], Data[[#This Row],[Average]], Data[STDEV], "<"&Data[[#This Row],[STDEV]])+1, "TBD") -> 3 | S22: 1 | T22: =Data[[#This Row],[Day Rank]]=Data[[#This Row],[W Rank]] -> FALSE
D23: =D22 -> 45462 | E23: =$K$1 -> danram | F23: =IFERROR(AVERAGE(Data[[#This Row],[alappatjoe]:[currydestroyer27]]), "TBD") -> 4.2 | G23: =IFERROR(_xlfn.STDEV.P(Data[[#This Row],[alappatjoe]:[currydestroyer27]]), "TBD") -> 0.74833148 | H23: The Wave | I23: SE SO NEON | J23: 4 | K23: 4 | L23: 5 | M23: 3 | N23: 5 | P23: International | Q23: Korean Alternative | R23: =IF(SUM(Data[[#This Row],[alappatjoe]:[currydestroyer27]])>0, COUNTIFS(Data[Date], Data[[#This Row],[Date]], Data[Average], "<"&Data[[#This Row],[Average]]) + COUNTIFS(Data[Date], Data[[#This Row],[Date]], Data[Average], Data[[#This Row],[Average]], Data[STDEV], "<"&Data[[#This Row],[STDEV]])+1, "TBD") -> 5 | S23: 1 | T23: =Data[[#This Row],[Day Rank]]=Data[[#This Row],[W Rank]] -> FALSE
D24: =D22 -> 45462 | E24: =$L$1 -> loganworsdell | F24: =IFERROR(AVERAGE(Data[[#This Row],[alappatjoe]:[currydestroyer27]]), "TBD") -> 4 | G24: =IFERROR(_xlfn.STDEV.P(Data[[#This Row],[alappatjoe]:[currydestroyer27]]), "TBD") -> 0.89442719 | H24: Intentions | I24: Hudson Mohawke | J24: 5 | K24: 3 | L24: 3 | M24: 5 | N24: 4 | P24: Electronic | Q24: Purple Sound | R24: =IF(SUM(Data[[#This Row],[alappatjoe]:[currydestroyer27]])>0, COUNTIFS(Data[Date], Data[[#This Row],[Date]], Data[Average], "<"&Data[[#This Row],[Average]]) + COUNTIFS(Data[Date], Data[[#This Row],[Date]], Data[Average], Data[[#This Row],[Average]], Data[STDEV], "<"&Data[[#This Row],[STDEV]])+1, "TBD") -> 4 | S24: 1 | T24: =Data[[#This Row],[Day Rank]]=Data[[#This Row],[W Rank]] -> FALSE
D25: =D22 -> 45462 | E25: =$M$1 -> samuelbattista | F25: =IFERROR(AVERAGE(Data[[#This Row],[alappatjoe]:[currydestroyer27]]), "TBD") -> 2.4 | G25: =IFERROR(_xlfn.STDEV.P(Data[[#This Row],[alappatjoe]:[currydestroyer27]]), "TBD") -> 1.0198039 | H25: Good Luck, Babe! | I25: Chappell Roan | J25: 3 | K25: 1 | L25: 4 | M25: 2 | N25: 2 | P25: Pop | Q25: Indie Pop | R25: =IF(SUM(Data[[#This Row],[alappatjoe]:[currydestroyer27]])>0, COUNTIFS(Data[Date], Data[[#This Row],[Date]], Data[Average], "<"&Data[[#This Row],[Average]]) + COUNTIFS(Data[Date], Data[[#This Row],[Date]], Data[Average], Data[[#This Row],[Average]], Data[STDEV], "<"&Data[[#This Row],[STDEV]])+1, "TBD") -> 2 | S25: 1 | T25: =Data[[#This Row],[Day Rank]]=Data[[#This Row],[W Rank]] -> FALSE
D26: =D22 -> 45462 | E26: =$N$1 -> currydestroyer27 | F26: =IFERROR(AVERAGE(Data[[#This Row],[alappatjoe]:[currydestroyer27]]), "TBD") -> 1.4 | G26: =IFERROR(_xlfn.STDEV.P(Data[[#This Row],[alappatjoe]:[currydestroyer27]]), "TBD") -> 0.48989795 | H26: Holdin Out for a Hero | I26: Bonnie Tyler | J26: 2 | K26: 2 | L26: 1 | M26: 1 | N26: 1 | P26: Rock | Q26: Rock | R26: =IF(SUM(Data[[#This Row],[alappatjoe]:[currydestroyer27]])>0, COUNTIFS(Data[Date], Data[[#This Row],[Date]], Data[Average], "<"&Data[[#This Row],[Average]]) + COUNTIFS(Data[Date], Data[[#This Row],[Date]], Data[Average], Data[[#This Row],[Average]], Data[STDEV], "<"&Data[[#This Row],[STDEV]])+1, "TBD") -> 1 | S26: 1 | T26: =Data[[#This Row],[Day Rank]]=Data[[#This Row],[W Rank]] -> TRUE
A27: 45463 | C27: {=_xlfn.LET(_xlpm.matches, _xlfn._xlws.FILTER(Data[Poster], (Data[Date]=A27)*(Data[Winner]=TRUE)), IF(ROWS(_xlpm.matches)>1, "TIE", _xlpm.matches))} -> alappatjoe | D27: =A27 -> 45463 | E27: =$J$1 -> alappatjoe | F27: =IFERROR(AVERAGE(Data[[#This Row],[alappatjoe]:[currydestroyer27]]), "TBD") -> 1.8 | G27: =IFERROR(_xlfn.STDEV.P(Data[[#This Row],[alappatjoe]:[currydestroyer27]]), "TBD") -> 0.4 | H27: Espresso | I27: Sabrina Carpenter | J27: 1 | K27: 2 | L27: 2 | M27: 2 | N27: 2 | P27: Pop | Q27: Pop | R27: =IF(SUM(Data[[#This Row],[alappatjoe]:[currydestroyer27]])>0, COUNTIFS(Data[Date], Data[[#This Row],[Date]], Data[Average], "<"&Data[[#This Row],[Average]]) + COUNTIFS(Data[Date], Data[[#This Row],[Date]], Data[Average], Data[[#This Row],[Average]], Data[STDEV], "<"&Data[[#This Row],[STDEV]])+1, "TBD") -> 1 | S27: 1 | T27: =Data[[#This Row],[Day Rank]]=Data[[#This Row],[W Rank]] -> TRUE
D28: =D27 -> 45463 | E28: =$K$1 -> danram | F28: =IFERROR(AVERAGE(Data[[#This Row],[alappatjoe]:[currydestroyer27]]), "TBD") -> 3.4 | G28: =IFERROR(_xlfn.STDEV.P(Data[[#This Row],[alappatjoe]:[currydestroyer27]]), "TBD") -> 1.356466 | H28: Instant Crush | I28: Daft Punk, Julian Casablancas | J28: 4 | K28: 3 | L28: 5 | M28: 4 | N28: 1 | P28: Rock | Q28: Dance-Rock | R28: =IF(SUM(Data[[#This Row],[alappatjoe]:[currydestroyer27]])>0, COUNTIFS(Data[Date], Data[[#This Row],[Date]], Data[Average], "<"&Data[[#This Row],[Average]]) + COUNTIFS(Data[Date], Data[[#This Row],[Date]], Data[Average], Data[[#This Row],[Average]], Data[STDEV], "<"&Data[[#This Row],[STDEV]])+1, "TBD") -> 3 | S28: 1 | T28: =Data[[#This Row],[Day Rank]]=Data[[#This Row],[W Rank]] -> FALSE
D29: =D27 -> 45463 | E29: =$L$1 -> loganworsdell | F29: =IFERROR(AVERAGE(Data[[#This Row],[alappatjoe]:[currydestroyer27]]), "TBD") -> 3.8 | G29: =IFERROR(_xlfn.STDEV.P(Data[[#This Row],[alappatjoe]:[currydestroyer27]]), "TBD") -> 1.1661904 | H29: Genghis Khan | I29: Miike Snow | J29: 2 | K29: 5 | L29: 4 | M29: 3 | N29: 5 | P29: Rock | Q29: Indietornica | R29: =IF(SUM(Data[[#This Row],[alappatjoe]:[currydestroyer27]])>0, COUNTIFS(Data[Date], Data[[#This Row],[Date]], Data[Average], "<"&Data[[#This Row],[Average]]) + COUNTIFS(Data[Date], Data[[#This Row],[Date]], Data[Average], Data[[#This Row],[Average]], Data[STDEV], "<"&Data[[#This Row],[STDEV]])+1, "TBD") -> 5 | S29: 1 | T29: =Data[[#This Row],[Day Rank]]=Data[[#This Row],[W Rank]] -> FALSE
D30: =D27 -> 45463 | E30: =$M$1 -> samuelbattista | F30: =IFERROR(AVERAGE(Data[[#This Row],[alappatjoe]:[currydestroyer27]]), "TBD") -> 2.4 | G30: =IFERROR(_xlfn.STDEV.P(Data[[#This Row],[alappatjoe]:[currydestroyer27]]), "TBD") -> 1.7435596 | H30: Bangarang | I30: Skrillex | J30: 5 | K30: 1 | L30: 1 | M30: 1 | N30: 4 | P30: Electronic | Q30: EDM | R30: =IF(SUM(Data[[#This Row],[alappatjoe]:[currydestroyer27]])>0, COUNTIFS(Data[Date], Data[[#This Row],[Date]], Data[Average], "<"&Data[[#This Row],[Average]]) + COUNTIFS(Data[Date], Data[[#This Row],[Date]], Data[Average], Data[[#This Row],[Average]], Data[STDEV], "<"&Data[[#This Row],[STDEV]])+1, "TBD") -> 2 | S30: 1 | T30: =Data[[#This Row],[Day Rank]]=Data[[#This Row],[W Rank]] -> FALSE
D31: =D27 -> 45463 | E31: =$N$1 -> currydestroyer27 | F31: =IFERROR(AVERAGE(Data[[#This Row],[alappatjoe]:[currydestroyer27]]), "TBD") -> 3.6 | G31: =IFERROR(_xlfn.STDEV.P(Data[[#This Row],[alappatjoe]:[currydestroyer27]]), "TBD") -> 0.8 | H31: Spruce | I31: Tori Kelly, Kim Chaewon | J31: 3 | K31: 4 | L31: 3 | M31: 5 | N31: 3 | P31: Pop | Q31: Pop | R31: =IF(SUM(Data[[#This Row],[alappatjoe]:[currydestroyer27]])>0, COUNTIFS(Data[Date], Data[[#This Row],[Date]], Data[Average], "<"&Data[[#This Row],[Average]]) + COUNTIFS(Data[Date], Data[[#This Row],[Date]], Data[Average], Data[[#This Row],[Average]], Data[STDEV], "<"&Data[[#This Row],[STDEV]])+1, "TBD") -> 4 | S31: 1 | T31: =Data[[#This Row],[Day Rank]]=Data[[#This Row],[W Rank]] -> FALSE
A32: 45467 | C32: {=_xlfn.LET(_xlpm.matches, _xlfn._xlws.FILTER(Data[Poster], (Data[Date]=A32)*(Data[Winner]=TRUE)), IF(ROWS(_xlpm.matches)>1, "TIE", _xlpm.matches))} -> loganworsdell | D32: =A32 -> 45467 | E32: =$J$1 -> alappatjoe | F32: =IFERROR(AVERAGE(Data[[#This Row],[alappatjoe]:[currydestroyer27]]), "TBD") -> 3.8 | G32: =IFERROR(_xlfn.STDEV.P(Data[[#This Row],[alappatjoe]:[currydestroyer27]]), "TBD") -> 0.9797959 | H32: Sher Khul Gaye | I32: Benny Dayal, Shilpa Rao, & more | J32: 2 | K32: 4 | L32: 4 | M32: 5 | N32: 4 | P32: International | Q32: Bollywood | R32: =IF(SUM(Data[[#This Row],[alappatjoe]:[currydestroyer27]])>0, COUNTIFS(Data[Date], Data[[#This Row],[Date]], Data[Average], "<"&Data[[#This Row],[Average]]) + COUNTIFS(Data[Date], Data[[#This Row],[Date]], Data[Average], Data[[#This Row],[Average]], Data[STDEV], "<"&Data[[#This Row],[STDEV]])+1, "TBD") -> 5 | S32: 1 | T32: =Data[[#This Row],[Day Rank]]=Data[[#This Row],[W Rank]] -> FALSE
D33: =D32 -> 45467 | E33: =$K$1 -> danram | F33: =IFERROR(AVERAGE(Data[[#This Row],[alappatjoe]:[currydestroyer27]]), "TBD") -> 2.6 | G33: =IFERROR(_xlfn.STDEV.P(Data[[#This Row],[alappatjoe]:[currydestroyer27]]), "TBD") -> 1.356466 | H33: Virgen | I33: Adolescent's Orquesta | J33: 1 | K33: 2 | L33: 5 | M33: 2 | N33: 3 | P33: International | Q33: Salsa | R33: =IF(SUM(Data[[#This Row],[alappatjoe]:[currydestroyer27]])>0, COUNTIFS(Data[Date], Data[[#This Row],[Date]], Data[Average], "<"&Data[[#This Row],[Average]]) + COUNTIFS(Data[Date], Data[[#This Row],[Date]], Data[Average], Data[[#This Row],[Average]], Data[STDEV], "<"&Data[[#This Row],[STDEV]])+1, "TBD") -> 2 | S33: 1 | T33: =Data[[#This Row],[Day Rank]]=Data[[#This Row],[W Rank]] -> FALSE
D34: =D32 -> 45467 | E34: =$L$1 -> loganworsdell | F34: =IFERROR(AVERAGE(Data[[#This Row],[alappatjoe]:[currydestroyer27]]), "TBD") -> 2.2 | G34: =IFERROR(_xlfn.STDEV.P(Data[[#This Row],[alappatjoe]:[currydestroyer27]]), "TBD") -> 1.6 | H34: Everything Goes On | I34: Porter Robinson, League of Legends | J34: 5 | K34: 1 | L34: 1 | M34: 3 | N34: 1 | P34: Electronic | Q34: Complextro | R34: =IF(SUM(Data[[#This Row],[alappatjoe]:[currydestroyer27]])>0, COUNTIFS(Data[Date], Data[[#This Row],[Date]], Data[Average], "<"&Data[[#This Row],[Average]]) + COUNTIFS(Data[Date], Data[[#This Row],[Date]], Data[Average], Data[[#This Row],[Average]], Data[STDEV], "<"&Data[[#This Row],[STDEV]])+1, "TBD") -> 1 | S34: 1 | T34: =Data[[#This Row],[Day Rank]]=Data[[#This Row],[W Rank]] -> TRUE
D35: =D32 -> 45467 | E35: =$M$1 -> samuelbattista | F35: =IFERROR(AVERAGE(Data[[#This Row],[alappatjoe]:[currydestroyer27]]), "TBD") -> 3 | G35: =IFERROR(_xlfn.STDEV.P(Data[[#This Row],[alappatjoe]:[currydestroyer27]]), "TBD") -> 1.4142136 | H35: High Horse | I35: Kacey Musgraves | J35: 4 | K35: 3 | L35: 2 | M35: 1 | N35: 5 | P35: Country | Q35: Contemporary Country | R35: =IF(SUM(Data[[#This Row],[alappatjoe]:[currydestroyer27]])>0, COUNTIFS(Data[Date], Data[[#This Row],[Date]], Data[Average], "<"&Data[[#This Row],[Average]]) + COUNTIFS(Data[Date], Data[[#This Row],[Date]], Data[Average], Data[[#This Row],[Average]], Data[STDEV], "<"&Data[[#This Row],[STDEV]])+1, "TBD") -> 3 | S35: 1 | T35: =Data[[#This Row],[Day Rank]]=Data[[#This Row],[W Rank]] -> FALSE
D36: =D32 -> 45467 | E36: =$N$1 -> currydestroyer27 | F36: =IFERROR(AVERAGE(Data[[#This Row],[alappatjoe]:[currydestroyer27]]), "TBD") -> 3.4 | G36: =IFERROR(_xlfn.STDEV.P(Data[[#This Row],[alappatjoe]:[currydestroyer27]]), "TBD") -> 1.0198039 | H36: Same Old Love Remix | I36: Selena Gomez, Fetty Wap | J36: 3 | K36: 5 | L36: 3 | M36: 4 | N36: 2 | P36: Pop | Q36: Pop | R36: =IF(SUM(Data[[#This Row],[alappatjoe]:[currydestroyer27]])>0, COUNTIFS(Data[Date], Data[[#This Row],[Date]], Data[Average], "<"&Data[[#This Row],[Average]]) + COUNTIFS(Data[Date], Data[[#This Row],[Date]], Data[Average], Data[[#This Row],[Average]], Data[STDEV], "<"&Data[[#This Row],[STDEV]])+1, "TBD") -> 4 | S36: 1 | T36: =Data[[#This Row],[Day Rank]]=Data[[#This Row],[W Rank]] -> FALSE
A37: 45468 | C37: {=_xlfn.LET(_xlpm.matches, _xlfn._xlws.FILTER(Data[Poster], (Data[Date]=A37)*(Data[Winner]=TRUE)), IF(ROWS(_xlpm.matches)>1, "TIE", _xlpm.matches))} -> currydestroyer27 | D37: =A37 -> 45468 | E37: =$J$1 -> alappatjoe | F37: =IFERROR(AVERAGE(Data[[#This Row],[alappatjoe]:[currydestroyer27]]), "TBD") -> 3.4 | G37: =IFERROR(_xlfn.STDEV.P(Data[[#This Row],[alappatjoe]:[currydestroyer27]]), "TBD") -> 1.6248077 | H37: Brand New World | I37: D-51 | J37: 1 | K37: 4 | L37: 5 | M37: 5 | N37: 2 | P37: International | R37: =IF(SUM(Data[[#This Row],[alappatjoe]:[currydestroyer27]])>0, COUNTIFS(Data[Date], Data[[#This Row],[Date]], Data[Average], "<"&Data[[#This Row],[Average]]) + COUNTIFS(Data[Date], Data[[#This Row],[Date]], Data[Average], Data[[#This Row],[Average]], Data[STDEV], "<"&Data[[#This Row],[STDEV]])+1, "TBD") -> 5 | S37: 1 | T37: =Data[[#This Row],[Day Rank]]=Data[[#This Row],[W Rank]] -> FALSE
D38: =D37 -> 45468 | E38: =$K$1 -> danram | F38: =IFERROR(AVERAGE(Data[[#This Row],[alappatjoe]:[currydestroyer27]]), "TBD") -> 3 | G38: =IFERROR(_xlfn.STDEV.P(Data[[#This Row],[alappatjoe]:[currydestroyer27]]), "TBD") -> 1.2649111 | H38: Psychopomp | I38: Thank You Scientist | J38: 3 | K38: 1 | L38: 3 | M38: 3 | N38: 5 | P38: Rock | Q38: Progressive Rock | R38: =IF(SUM(Data[[#This Row],[alappatjoe]:[currydestroyer27]])>0, COUNTIFS(Data[Date], Data[[#This Row],[Date]], Data[Average], "<"&Data[[#This Row],[Average]]) + COUNTIFS(Data[Date], Data[[#This Row],[Date]], Data[Average], Data[[#This Row],[Average]], Data[STDEV], "<"&Data[[#This Row],[STDEV]])+1, "TBD") -> 3 | S38: 1 | T38: =Data[[#This Row],[Day Rank]]=Data[[#This Row],[W Rank]] -> FALSE
D39: =D37 -> 45468 | E39: =$L$1 -> loganworsdell | F39: =IFERROR(AVERAGE(Data[[#This Row],[alappatjoe]:[currydestroyer27]]), "TBD") -> 3 | G39: =IFERROR(_xlfn.STDEV.P(Data[[#This Row],[alappatjoe]:[currydestroyer27]]), "TBD") -> 0.89442719 | H39: Really good cry | I39: BETWEEN FRIENDS | J39: 4 | K39: 2 | L39: 4 | M39: 2 | N39: 3 | P39: Pop | Q39: Indie Pop | R39: =IF(SUM(Data[[#This Row],[alappatjoe]:[currydestroyer27]])>0, COUNTIFS(Data[Date], Data[[#This Row],[Date]], Data[Average], "<"&Data[[#This Row],[Average]]) + COUNTIFS(Data[Date], Data[[#This Row],[Date]], Data[Average], Data[[#This Row],[Average]], Data[STDEV], "<"&Data[[#This Row],[STDEV]])+1, "TBD") -> 2 | S39: 1 | T39: =Data[[#This Row],[Day Rank]]=Data[[#This Row],[W Rank]] -> FALSE
D40: =D37 -> 45468 | E40: =$M$1 -> samuelbattista | F40: =IFERROR(AVERAGE(Data[[#This Row],[alappatjoe]:[currydestroyer27]]), "TBD") -> 3 | G40: =IFERROR(_xlfn.STDEV.P(Data[[#This Row],[alappatjoe]:[currydestroyer27]]), "TBD") -> 1.4142136 | H40: ABC | I40: Polyphia, Sophia Black | J40: 5 | K40: 3 | L40: 2 | M40: 1 | N40: 4 | P40: Metal | Q40: Progressive Metal | R40: =IF(SUM(Data[[#This Row],[alappatjoe]:[currydestroyer27]])>0, COUNTIFS(Data[Date], Data[[#This Row],[Date]], Data[Average], "<"&Data[[#This Row],[Average]]) + COUNTIFS(Data[Date], Data[[#This Row],[Date]], Data[Average], Data[[#This Row],[Average]], Data[STDEV], "<"&Data[[#This Row],[STDEV]])+1, "TBD") -> 4 | S40: 1 | T40: =Data[[#This Row],[Day Rank]]=Data[[#This Row],[W Rank]] -> FALSE
...

Sheet Leaderboard
B2: =_xlfn.CONCAT("Day ",COUNTIF(Rankings!A:A,"<="&TODAY())) -> Day 445 | C2: Number of Wins | D2: Sum of Average | E2: Overall Average | F2: Place | G2: Constructors | I2: Poster\Day Rank | J2: 1 | K2: 2 | L2: 3 | M2: 4 | N2: 5 | P2: Plays | Q2: Mean | R2: 1B+ | S2: Median | T2: Min | U2: Max
B3: =Rankings!$J$1 -> alappatjoe | C3: =COUNTIFS(Data[[Poster]:[Poster]],$B3, Data[Winner],TRUE()) -> 87 | D3: {=SUM(IF(Data[Poster]=$B3, Data[Average]))} -> 1354.4 | E3: {=AVERAGE(IF(Data[Poster]=$B3, Data[Average]))} -> 3.0435955 | F3: =_xlfn.RANK.EQ(C3,$C$3:$C$7,0) -> 4 | G3: =_xlfn.RANK.EQ(E3,$E$3:$E$7,1) -> 4 | I3: =Rankings!$J$1 -> alappatjoe | J3: =COUNTIFS(Data[[Poster]:[Poster]],$I3, Data[[Day Rank]:[Day Rank]],J$2) -> 91 | K3: =COUNTIFS(Data[[Poster]:[Poster]],$I3, Data[[Day Rank]:[Day Rank]],K$2) -> 64 | L3: =COUNTIFS(Data[[Poster]:[Poster]],$I3, Data[[Day Rank]:[Day Rank]],L$2) -> 96 | M3: =COUNTIFS(Data[[Poster]:[Poster]],$I3, Data[[Day Rank]:[Day Rank]],M$2) -> 96 | N3: =COUNTIFS(Data[[Poster]:[Poster]],$I3, Data[[Day Rank]:[Day Rank]],N$2) -> 98 | P3: =Rankings!$J$1 -> alappatjoe | Q3: {=AVERAGE(IF(Data[Poster]=$P3, IF(Data[Plays]>0, Data[Plays])))} -> 1.757084e+08 | R3: =COUNTIFS(Data[[Poster]:[Poster]],$I3, Data[[Plays]:[Plays]],">="&1000000000) -> 13 | S3: {=MEDIAN(IF(Data[Poster]=$P3, IF(Data[Plays]>0, Data[Plays])))} -> 4921398 | T3: {=MIN(IF(Data[Poster]=$P3, IF(Data[Plays]>0, Data[Plays])))} -> 999 | U3: {=MAX(IF(Data[Poster]=$P3, IF(Data[Plays]>0, Data[Plays])))} -> 3355842640
B4: =Rankings!$K$1 -> danram | C4: =COUNTIFS(Data[[Poster]:[Poster]],$B4, Data[Winner],TRUE()) -> 89 | D4: {=SUM(IF(Data[Poster]=$B4, Data[Average]))} -> 1393.6 | E4: {=AVERAGE(IF(Data[Poster]=$B4, Data[Average]))} -> 3.1316854 | F4: =_xlfn.RANK.EQ(C4,$C$3:$C$7,0) -> 3 | G4: =_xlfn.RANK.EQ(E4,$E$3:$E$7,1) -> 5 | I4: =Rankings!$K$1 -> danram | J4: =COUNTIFS(Data[[Poster]:[Poster]],$I4, Data[[Day Rank]:[Day Rank]],J$2) -> 89 | K4: =COUNTIFS(Data[[Poster]:[Poster]],$I4, Data[[Day Rank]:[Day Rank]],K$2) -> 81 | L4: =COUNTIFS(Data[[Poster]:[Poster]],$I4, Data[[Day Rank]:[Day Rank]],L$2) -> 68 | M4: =COUNTIFS(Data[[Poster]:[Poster]],$I4, Data[[Day Rank]:[Day Rank]],M$2) -> 98 | N4: =COUNTIFS(Data[[Poster]:[Poster]],$I4, Data[[Day Rank]:[Day Rank]],N$2) -> 109 | P4: =Rankings!$K$1 -> danram | Q4: {=AVERAGE(IF(Data[Poster]=$P4, IF(Data[Plays]>0, Data[Plays])))} -> 9.4006842e+08 | R4: =COUNTIFS(Data[[Poster]:[Poster]],$I4, Data[[Plays]:[Plays]],">="&1000000000) -> 10 | S4: {=MEDIAN(IF(Data[Poster]=$P4, IF(Data[Plays]>0, Data[Plays])))} -> 629447417 | T4: {=MIN(IF(Data[Poster]=$P4, IF(Data[Plays]>0, Data[Plays])))} -> 667073 | U4: {=MAX(IF(Data[Poster]=$P4, IF(Data[Plays]>0, Data[Plays])))} -> 4454441248
B5: =Rankings!$L$1 -> loganworsdell | C5: =COUNTIFS(Data[[Poster]:[Poster]],$B5, Data[Winner],TRUE()) -> 90 | D5: {=SUM(IF(Data[Poster]=$B5, Data[Average]))} -> 1339.4 | E5: {=AVERAGE(IF(Data[Poster]=$B5, Data[Average]))} -> 3.0098876 | F5: =_xlfn.RANK.EQ(C5,$C$3:$C$7,0) -> 2 | G5: =_xlfn.RANK.EQ(E5,$E$3:$E$7,1) -> 3 | I5: =Rankings!$L$1 -> loganworsdell | J5: =COUNTIFS(Data[[Poster]:[Poster]],$I5, Data[[Day Rank]:[Day Rank]],J$2) -> 93 | K5: =COUNTIFS(Data[[Poster]:[Poster]],$I5, Data[[Day Rank]:[Day Rank]],K$2) -> 92 | L5: =COUNTIFS(Data[[Poster]:[Poster]],$I5, Data[[Day Rank]:[Day Rank]],L$2) -> 84 | M5: =COUNTIFS(Data[[Poster]:[Poster]],$I5, Data[[Day Rank]:[Day Rank]],M$2) -> 91 | N5: =COUNTIFS(Data[[Poster]:[Poster]],$I5, Data[[Day Rank]:[Day Rank]],N$2) -> 85 | P5: =Rankings!$L$1 -> loganworsdell | Q5: {=AVERAGE(IF(Data[Poster]=$P5, IF(Data[Plays]>0, Data[Plays])))} -> 1.4136032e+08 | R5: =COUNTIFS(Data[[Poster]:[Poster]],$I5, Data[[Plays]:[Plays]],">="&1000000000) -> 10 | S5: {=MEDIAN(IF(Data[Poster]=$P5, IF(Data[Plays]>0, Data[Plays])))} -> 7367511 | T5: {=MIN(IF(Data[Poster]=$P5, IF(Data[Plays]>0, Data[Plays])))} -> 999 | U5: {=MAX(IF(Data[Poster]=$P5, IF(Data[Plays]>0, Data[Plays])))} -> 3869670265
B6: =Rankings!$M$1 -> samuelbattista | C6: =COUNTIFS(Data[[Poster]:[Poster]],$B6, Data[Winner],TRUE()) -> 87 | D6: {=SUM(IF(Data[Poster]=$B6, Data[Average]))} -> 1306.2 | E6: {=AVERAGE(IF(Data[Poster]=$B6, Data[Average]))} -> 2.9352809 | F6: =_xlfn.RANK.EQ(C6,$C$3:$C$7,0) -> 4 | G6: =_xlfn.RANK.EQ(E6,$E$3:$E$7,1) -> 2 | I6: =Rankings!$M$1 -> samuelbattista | J6: =COUNTIFS(Data[[Poster]:[Poster]],$I6, Data[[Day Rank]:[Day Rank]],J$2) -> 92 | K6: =COUNTIFS(Data[[Poster]:[Poster]],$I6, Data[[Day Rank]:[Day Rank]],K$2) -> 107 | L6: =COUNTIFS(Data[[Poster]:[Poster]],$I6, Data[[Day Rank]:[Day Rank]],L$2) -> 96 | M6: =COUNTIFS(Data[[Poster]:[Poster]],$I6, Data[[Day Rank]:[Day Rank]],M$2) -> 76 | N6: =COUNTIFS(Data[[Poster]:[Poster]],$I6, Data[[Day Rank]:[Day Rank]],N$2) -> 74 | P6: =Rankings!$M$1 -> samuelbattista | Q6: {=AVERAGE(IF(Data[Poster]=$P6, IF(Data[Plays]>0, Data[Plays])))} -> 4.3092698e+08 | R6: =COUNTIFS(Data[[Poster]:[Poster]],$I6, Data[[Plays]:[Plays]],">="&1000000000) -> 7 | S6: {=MEDIAN(IF(Data[Poster]=$P6, IF(Data[Plays]>0, Data[Plays])))} -> 27496238 | T6: {=MIN(IF(Data[Poster]=$P6, IF(Data[Plays]>0, Data[Plays])))} -> 40645 | U6: {=MAX(IF(Data[Poster]=$P6, IF(Data[Plays]>0, Data[Plays])))} -> 5351958417
B7: =Rankings!$N$1 -> currydestroyer27 | C7: =COUNTIFS(Data[[Poster]:[Poster]],$B7, Data[Winner],TRUE()) -> 92 | D7: {=SUM(IF(Data[Poster]=$B7, Data[Average]))} -> 1281.4 | E7: {=AVERAGE(IF(Data[Poster]=$B7, Data[Average]))} -> 2.8795506 | F7: =_xlfn.RANK.EQ(C7,$C$3:$C$7,0) -> 1 | G7: =_xlfn.RANK.EQ(E7,$E$3:$E$7,1) -> 1 | I7: =Rankings!$N$1 -> currydestroyer27 | J7: =COUNTIFS(Data[[Poster]:[Poster]],$I7, Data[[Day Rank]:[Day Rank]],J$2) -> 96 | K7: =COUNTIFS(Data[[Poster]:[Poster]],$I7, Data[[Day Rank]:[Day Rank]],K$2) -> 104 | L7: =COUNTIFS(Data[[Poster]:[Poster]],$I7, Data[[Day Rank]:[Day Rank]],L$2) -> 93 | M7: =COUNTIFS(Data[[Poster]:[Poster]],$I7, Data[[Day Rank]:[Day Rank]],M$2) -> 83 | N7: =COUNTIFS(Data[[Poster]:[Poster]],$I7, Data[[Day Rank]:[Day Rank]],N$2) -> 69 | P7: =Rankings!$N$1 -> currydestroyer27 | Q7: {=AVERAGE(IF(Data[Poster]=$P7, IF(Data[Plays]>0, Data[Plays])))} -> 2.6256088e+08 | R7: =COUNTIFS(Data[[Poster]:[Poster]],$I7, Data[[Plays]:[Plays]],">="&1000000000) -> 17 | S7: {=MEDIAN(IF(Data[Poster]=$P7, IF(Data[Plays]>0, Data[Plays])))} -> 63260342 | T7: {=MIN(IF(Data[Poster]=$P7, IF(Data[Plays]>0, Data[Plays])))} -> 3000 | U7: {=MAX(IF(Data[Poster]=$P7, IF(Data[Plays]>0, Data[Plays])))} -> 2883211530
B9: Average Rank for past | E9: 28 | F9: days | I9: Median Rank for past | L9: 28 | M9: days | P9: 1 | Q9: =_xlfn.CONCAT("Amount of ",P9,"'s given for past") -> Amount of 1's given for past | T9: 1000 | U9: days | V9: Sum | X9: 2 | Y9: =_xlfn.CONCAT("Amount of ",X9,"'s given for past") -> Amount of 2's given for past | AB9: 1000 | AC9: days | AD9: Sum
B10: Poster\Voter | C10: =Rankings!$J$1 -> alappatjoe | D10: =Rankings!$K$1 -> danram | E10: =Rankings!$L$1 -> loganworsdell | F10: =Rankings!$M$1 -> samuelbattista | G10: =Rankings!$N$1 -> currydestroyer27 | I10: Poster\Voter | J10: =Rankings!$J$1 -> alappatjoe | K10: =Rankings!$K$1 -> danram | L10: =Rankings!$L$1 -> loganworsdell | M10: =Rankings!$M$1 -> samuelbattista | N10: =Rankings!$N$1 -> currydestroyer27 | P10: Poster\Voter | Q10: =Rankings!$J$1 -> alappatjoe | R10: =Rankings!$K$1 -> danram | S10: =Rankings!$L$1 -> loganworsdell | T10: =Rankings!$M$1 -> samuelbattista | U10: =Rankings!$N$1 -> currydestroyer27 | X10: Poster\Voter | Y10: =Rankings!$J$1 -> alappatjoe | Z10: =Rankings!$K$1 -> danram | AA10: =Rankings!$L$1 -> loganworsdell | AB10: =Rankings!$M$1 -> samuelbattista | AC10: =Rankings!$N$1 -> currydestroyer27
B11: =Rankings!$J$1 -> alappatjoe | C11: {=AVERAGE(IF(Data[Poster]=$B11, IF(Data[Date]> TODAY()-$E$9, IF(INDIRECT(_xlfn.CONCAT("Data[", C$10, "]"))>0, INDIRECT(_xlfn.CONCAT("Data[", C$10, "]"))))))} -> 1.375 | D11: {=AVERAGE(IF(Data[Poster]=$B11, IF(Data[Date]> TODAY()-$E$9, IF(INDIRECT(_xlfn.CONCAT("Data[", D$10, "]"))>0, INDIRECT(_xlfn.CONCAT("Data[", D$10, "]"))))))} -> 3.4375 | E11: {=AVERAGE(IF(Data[Poster]=$B11, IF(Data[Date]> TODAY()-$E$9, IF(INDIRECT(_xlfn.CONCAT("Data[", E$10, "]"))>0, INDIRECT(_xlfn.CONCAT("Data[", E$10, "]"))))))} -> 3 | F11: {=AVERAGE(IF(Data[Poster]=$B11, IF(Data[Date]> TODAY()-$E$9, IF(INDIRECT(_xlfn.CONCAT("Data[", F$10, "]"))>0, INDIRECT(_xlfn.CONCAT("Data[", F$10, "]"))))))} -> 3.5625 | G11: {=AVERAGE(IF(Data[Poster]=$B11, IF(Data[Date]> TODAY()-$E$9, IF(INDIRECT(_xlfn.CONCAT("Data[", G$10, "]"))>0, INDIRECT(_xlfn.CONCAT("Data[", G$10, "]"))))))} -> 3.0625 | I11: =Rankings!$J$1 -> alappatjoe | J11: {=MEDIAN(IF(Data[Poster]=$I11, IF(Data[Date]> TODAY()-$L$9, IF(INDIRECT(_xlfn.CONCAT("Data[", J$10, "]"))>0, INDIRECT(_xlfn.CONCAT("Data[", J$10, "]"))))))} -> 1 | K11: {=MEDIAN(IF(Data[Poster]=$I11, IF(Data[Date]> TODAY()-$L$9, IF(INDIRECT(_xlfn.CONCAT("Data[", K$10, "]"))>0, INDIRECT(_xlfn.CONCAT("Data[", K$10, "]"))))))} -> 3.5 | L11: {=MEDIAN(IF(Data[Poster]=$I11, IF(Data[Date]> TODAY()-$L$9, IF(INDIRECT(_xlfn.CONCAT("Data[", L$10, "]"))>0, INDIRECT(_xlfn.CONCAT("Data[", L$10, "]"))))))} -> 3 | M11: {=MEDIAN(IF(Data[Poster]=$I11, IF(Data[Date]> TODAY()-$L$9, IF(INDIRECT(_xlfn.CONCAT("Data[", M$10, "]"))>0, INDIRECT(_xlfn.CONCAT("Data[", M$10, "]"))))))} -> 4 | N11: {=MEDIAN(IF(Data[Poster]=$I11, IF(Data[Date]> TODAY()-$L$9, IF(INDIRECT(_xlfn.CONCAT("Data[", N$10, "]"))>0, INDIRECT(_xlfn.CONCAT("Data[", N$10, "]"))))))} -> 3 | P11: =Rankings!$J$1 -> alappatjoe | Q11: =COUNTIFS(Data[Date],">"&TODAY()-$T$9,Data[Poster],$P11,INDIRECT(_xlfn.CONCAT("Data[", Q$10, "]")),$P$9) -> 384 | R11: =COUNTIFS(Data[Date],">"&TODAY()-$T$9,Data[Poster],$P11,INDIRECT(_xlfn.CONCAT("Data[", R$10, "]")),$P$9) -> 29 | S11: =COUNTIFS(Data[Date],">"&TODAY()-$T$9,Data[Poster],$P11,INDIRECT(_xlfn.CONCAT("Data[", S$10, "]")),$P$9) -> 38 | T11: =COUNTIFS(Data[Date],">"&TODAY()-$T$9,Data[Poster],$P11,INDIRECT(_xlfn.CONCAT("Data[", T$10, "]")),$P$9) -> 17 | U11: =COUNTIFS(Data[Date],">"&TODAY()-$T$9,Data[Poster],$P11,INDIRECT(_xlfn.CONCAT("Data[", U$10, "]")),$P$9) -> 33 | V11: =SUM(Q11:U11) -> 501 | X11: =Rankings!$J$1 -> alappatjoe | Y11: =COUNTIFS(Data[Date],">"&TODAY()-$AB$9,Data[Poster],$X11,INDIRECT(_xlfn.CONCAT("Data[", Y$10, "]")),$X$9) -> 38 | Z11: =COUNTIFS(Data[Date],">"&TODAY()-$AB$9,Data[Poster],$X11,INDIRECT(_xlfn.CONCAT("Data[", Z$10, "]")),$X$9) -> 68 | AA11: =COUNTIFS(Data[Date],">"&TODAY()-$AB$9,Data[Poster],$X11,INDIRECT(_xlfn.CONCAT("Data[", AA$10, "]")),$X$9) -> 71 | AB11: =COUNTIFS(Data[Date],">"&TODAY()-$AB$9,Data[Poster],$X11,INDIRECT(_xlfn.CONCAT("Data[", AB$10, "]")),$X$9) -> 77 | AC11: =COUNTIFS(Data[Date],">"&TODAY()-$AB$9,Data[Poster],$X11,INDIRECT(_xlfn.CONCAT("Data[", AC$10, "]")),$X$9) -> 118 | AD11: =SUM(Y11:AC11) -> 372
B12: =Rankings!$K$1 -> danram | C12: {=AVERAGE(IF(Data[Poster]=$B12, IF(Data[Date]> TODAY()-$E$9, IF(INDIRECT(_xlfn.CONCAT("Data[", C$10, "]"))>0, INDIRECT(_xlfn.CONCAT("Data[", C$10, "]"))))))} -> 3.6875 | D12: {=AVERAGE(IF(Data[Poster]=$B12, IF(Data[Date]> TODAY()-$E$9, IF(INDIRECT(_xlfn.CONCAT("Data[", D$10, "]"))>0, INDIRECT(_xlfn.CONCAT("Data[", D$10, "]"))))))} -> 2.25 | E12: {=AVERAGE(IF(Data[Poster]=$B12, IF(Data[Date]> TODAY()-$E$9, IF(INDIRECT(_xlfn.CONCAT("Data[", E$10, "]"))>0, INDIRECT(_xlfn.CONCAT("Data[", E$10, "]"))))))} -> 4.0625 | F12: {=AVERAGE(IF(Data[Poster]=$B12, IF(Data[Date]> TODAY()-$E$9, IF(INDIRECT(_xlfn.CONCAT("Data[", F$10, "]"))>0, INDIRECT(_xlfn.CONCAT("Data[", F$10, "]"))))))} -> 2.8125 | G12: {=AVERAGE(IF(Data[Poster]=$B12, IF(Data[Date]> TODAY()-$E$9, IF(INDIRECT(_xlfn.CONCAT("Data[", G$10, "]"))>0, INDIRECT(_xlfn.CONCAT("Data[", G$10, "]"))))))} -> 3.5625 | I12: =Rankings!$K$1 -> danram | J12: {=MEDIAN(IF(Data[Poster]=$I12, IF(Data[Date]> TODAY()-$L$9, IF(INDIRECT(_xlfn.CONCAT("Data[", J$10, "]"))>0, INDIRECT(_xlfn.CONCAT("Data[", J$10, "]"))))))} -> 4 | K12: {=MEDIAN(IF(Data[Poster]=$I12, IF(Data[Date]> TODAY()-$L$9, IF(INDIRECT(_xlfn.CONCAT("Data[", K$10, "]"))>0, INDIRECT(_xlfn.CONCAT("Data[", K$10, "]"))))))} -> 1.5 | L12: {=MEDIAN(IF(Data[Poster]=$I12, IF(Data[Date]> TODAY()-$L$9, IF(INDIRECT(_xlfn.CONCAT("Data[", L$10, "]"))>0, INDIRECT(_xlfn.CONCAT("Data[", L$10, "]"))))))} -> 5 | M12: {=MEDIAN(IF(Data[Poster]=$I12, IF(Data[Date]> TODAY()-$L$9, IF(INDIRECT(_xlfn.CONCAT("Data[", M$10, "]"))>0, INDIRECT(_xlfn.CONCAT("Data[", M$10, "]"))))))} -> 2 | N12: {=MEDIAN(IF(Data[Poster]=$I12, IF(Data[Date]> TODAY()-$L$9, IF(INDIRECT(_xlfn.CONCAT("Data[", N$10, "]"))>0, INDIRECT(_xlfn.CONCAT("Data[", N$10, "]"))))))} -> 4 | P12: =Rankings!$K$1 -> danram | Q12: =COUNTIFS(Data[Date],">"&TODAY()-$T$9,Data[Poster],$P12,INDIRECT(_xlfn.CONCAT("Data[", Q$10, "]")),$P$9) -> 17 | R12: =COUNTIFS(Data[Date],">"&TODAY()-$T$9,Data[Poster],$P12,INDIRECT(_xlfn.CONCAT("Data[", R$10, "]")),$P$9) -> 238 | S12: =COUNTIFS(Data[Date],">"&TODAY()-$T$9,Data[Poster],$P12,INDIRECT(_xlfn.CONCAT("Data[", S$10, "]")),$P$9) -> 52 | T12: =COUNTIFS(Data[Date],">"&TODAY()-$T$9,Data[Poster],$P12,INDIRECT(_xlfn.CONCAT("Data[", T$10, "]")),$P$9) -> 33 | U12: =COUNTIFS(Data[Date],">"&TODAY()-$T$9,Data[Poster],$P12,INDIRECT(_xlfn.CONCAT("Data[", U$10, "]")),$P$9) -> 25 | V12: =SUM(Q12:U12) -> 365 | X12: =Rankings!$K$1 -> danram | Y12: =COUNTIFS(Data[Date],">"&TODAY()-$AB$9,Data[Poster],$X12,INDIRECT(_xlfn.CONCAT("Data[", Y$10, "]")),$X$9) -> 82 | Z12: =COUNTIFS(Data[Date],">"&TODAY()-$AB$9,Data[Poster],$X12,INDIRECT(_xlfn.CONCAT("Data[", Z$10, "]")),$X$9) -> 90 | AA12: =COUNTIFS(Data[Date],">"&TODAY()-$AB$9,Data[Poster],$X12,INDIRECT(_xlfn.CONCAT("Data[", AA$10, "]")),$X$9) -> 59 | AB12: =COUNTIFS(Data[Date],">"&TODAY()-$AB$9,Data[Poster],$X12,INDIRECT(_xlfn.CONCAT("Data[", AB$10, "]")),$X$9) -> 120 | AC12: =COUNTIFS(Data[Date],">"&TODAY()-$AB$9,Data[Poster],$X12,INDIRECT(_xlfn.CONCAT("Data[", AC$10, "]")),$X$9) -> 97 | AD12: =SUM(Y12:AC12) -> 448
B13: =Rankings!$L$1 -> loganworsdell | C13: {=AVERAGE(IF(Data[Poster]=$B13, IF(Data[Date]> TODAY()-$E$9, IF(INDIRECT(_xlfn.CONCAT("Data[", C$10, "]"))>0, INDIRECT(_xlfn.CONCAT("Data[", C$10, "]"))))))} -> 3.0625 | D13: {=AVERAGE(IF(Data[Poster]=$B13, IF(Data[Date]> TODAY()-$E$9, IF(INDIRECT(_xlfn.CONCAT("Data[", D$10, "]"))>0, INDIRECT(_xlfn.CONCAT("Data[", D$10, "]"))))))} -> 3.1875 | E13: {=AVERAGE(IF(Data[Poster]=$B13, IF(Data[Date]> TODAY()-$E$9, IF(INDIRECT(_xlfn.CONCAT("Data[", E$10, "]"))>0, INDIRECT(_xlfn.CONCAT("Data[", E$10, "]"))))))} -> 1.8125 | F13: {=AVERAGE(IF(Data[Poster]=$B13, IF(Data[Date]> TODAY()-$E$9, IF(INDIRECT(_xlfn.CONCAT("Data[", F$10, "]"))>0, INDIRECT(_xlfn.CONCAT("Data[", F$10, "]"))))))} -> 3.5 | G13: {=AVERAGE(IF(Data[Poster]=$B13, IF(Data[Date]> TODAY()-$E$9, IF(INDIRECT(_xlfn.CONCAT("Data[", G$10, "]"))>0, INDIRECT(_xlfn.CONCAT("Data[", G$10, "]"))))))} -> 3.4375 | I13: =Rankings!$L$1 -> loganworsdell | J13: {=MEDIAN(IF(Data[Poster]=$I13, IF(Data[Date]> TODAY()-$L$9, IF(INDIRECT(_xlfn.CONCAT("Data[", J$10, "]"))>0, INDIRECT(_xlfn.CONCAT("Data[", J$10, "]"))))))} -> 2.5 | K13: {=MEDIAN(IF(Data[Poster]=$I13, IF(Data[Date]> TODAY()-$L$9, IF(INDIRECT(_xlfn.CONCAT("Data[", K$10, "]"))>0, INDIRECT(_xlfn.CONCAT("Data[", K$10, "]"))))))} -> 3 | L13: {=MEDIAN(IF(Data[Poster]=$I13, IF(Data[Date]> TODAY()-$L$9, IF(INDIRECT(_xlfn.CONCAT("Data[", L$10, "]"))>0, INDIRECT(_xlfn.CONCAT("Data[", L$10, "]"))))))} -> 1.5 | M13: {=MEDIAN(IF(Data[Poster]=$I13, IF(Data[Date]> TODAY()-$L$9, IF(INDIRECT(_xlfn.CONCAT("Data[", M$10, "]"))>0, INDIRECT(_xlfn.CONCAT("Data[", M$10, "]"))))))} -> 3 | N13: {=MEDIAN(IF(Data[Poster]=$I13, IF(Data[Date]> TODAY()-$L$9, IF(INDIRECT(_xlfn.CONCAT("Data[", N$10, "]"))>0, INDIRECT(_xlfn.CONCAT("Data[", N$10, "]"))))))} -> 3 | P13: =Rankings!$L$1 -> loganworsdell | Q13: =COUNTIFS(Data[Date],">"&TODAY()-$T$9,Data[Poster],$P13,INDIRECT(_xlfn.CONCAT("Data[", Q$10, "]")),$P$9) -> 17 | R13: =COUNTIFS(Data[Date],">"&TODAY()-$T$9,Data[Poster],$P13,INDIRECT(_xlfn.CONCAT("Data[", R$10, "]")),$P$9) -> 61 | S13: =COUNTIFS(Data[Date],">"&TODAY()-$T$9,Data[Poster],$P13,INDIRECT(_xlfn.CONCAT("Data[", S$10, "]")),$P$9) -> 215 | T13: =COUNTIFS(Data[Date],">"&TODAY()-$T$9,Data[Poster],$P13,INDIRECT(_xlfn.CONCAT("Data[", T$10, "]")),$P$9) -> 15 | U13: =COUNTIFS(Data[Date],">"&TODAY()-$T$9,Data[Poster],$P13,INDIRECT(_xlfn.CONCAT("Data[", U$10, "]")),$P$9) -> 37 | V13: =SUM(Q13:U13) -> 345 | X13: =Rankings!$L$1 -> loganworsdell | Y13: =COUNTIFS(Data[Date],">"&TODAY()-$AB$9,Data[Poster],$X13,INDIRECT(_xlfn.CONCAT("Data[", Y$10, "]")),$X$9) -> 118 | Z13: =COUNTIFS(Data[Date],">"&TODAY()-$AB$9,Data[Poster],$X13,INDIRECT(_xlfn.CONCAT("Data[", Z$10, "]")),$X$9) -> 87 | AA13: =COUNTIFS(Data[Date],">"&TODAY()-$AB$9,Data[Poster],$X13,INDIRECT(_xlfn.CONCAT("Data[", AA$10, "]")),$X$9) -> 122 | AB13: =COUNTIFS(Data[Date],">"&TODAY()-$AB$9,Data[Poster],$X13,INDIRECT(_xlfn.CONCAT("Data[", AB$10, "]")),$X$9) -> 105 | AC13: =COUNTIFS(Data[Date],">"&TODAY()-$AB$9,Data[Poster],$X13,INDIRECT(_xlfn.CONCAT("Data[", AC$10, "]")),$X$9) -> 83 | AD13: =SUM(Y13:AC13) -> 515
B14: =Rankings!$M$1 -> samuelbattista | C14: {=AVERAGE(IF(Data[Poster]=$B14, IF(Data[Date]> TODAY()-$E$9, IF(INDIRECT(_xlfn.CONCAT("Data[", C$10, "]"))>0, INDIRECT(_xlfn.CONCAT("Data[", C$10, "]"))))))} -> 3.625 | D14: {=AVERAGE(IF(Data[Poster]=$B14, IF(Data[Date]> TODAY()-$E$9, IF(INDIRECT(_xlfn.CONCAT("Data[", D$10, "]"))>0, INDIRECT(_xlfn.CONCAT("Data[", D$10, "]"))))))} -> 3.25 | E14: {=AVERAGE(IF(Data[Poster]=$B14, IF(Data[Date]> TODAY()-$E$9, IF(INDIRECT(_xlfn.CONCAT("Data[", E$10, "]"))>0, INDIRECT(_xlfn.CONCAT("Data[", E$10, "]"))))))} -> 3.0625 | F14: {=AVERAGE(IF(Data[Poster]=$B14, IF(Data[Date]> TODAY()-$E$9, IF(INDIRECT(_xlfn.CONCAT("Data[", F$10, "]"))>0, INDIRECT(_xlfn.CONCAT("Data[", F$10, "]"))))))} -> 1.4375 | G14: {=AVERAGE(IF(Data[Poster]=$B14, IF(Data[Date]> TODAY()-$E$9, IF(INDIRECT(_xlfn.CONCAT("Data[", G$10, "]"))>0, INDIRECT(_xlfn.CONCAT("Data[", G$10, "]"))))))} -> 3.3125 | I14: =Rankings!$M$1 -> samuelbattista | J14: {=MEDIAN(IF(Data[Poster]=$I14, IF(Data[Date]> TODAY()-$L$9, IF(INDIRECT(_xlfn.CONCAT("Data[", J$10, "]"))>0, INDIRECT(_xlfn.CONCAT("Data[", J$10, "]"))))))} -> 4 | K14: {=MEDIAN(IF(Data[Poster]=$I14, IF(Data[Date]> TODAY()-$L$9, IF(INDIRECT(_xlfn.CONCAT("Data[", K$10, "]"))>0, INDIRECT(_xlfn.CONCAT("Data[", K$10, "]"))))))} -> 3 | L14: {=MEDIAN(IF(Data[Poster]=$I14, IF(Data[Date]> TODAY()-$L$9, IF(INDIRECT(_xlfn.CONCAT("Data[", L$10, "]"))>0, INDIRECT(_xlfn.CONCAT("Data[", L$10, "]"))))))} -> 3.5 | M14: {=MEDIAN(IF(Data[Poster]=$I14, IF(Data[Date]> TODAY()-$L$9, IF(INDIRECT(_xlfn.CONCAT("Data[", M$10, "]"))>0, INDIRECT(_xlfn.CONCAT("Data[", M$10, "]"))))))} -> 1 | N14: {=MEDIAN(IF(Data[Poster]=$I14, IF(Data[Date]> TODAY()-$L$9, IF(INDIRECT(_xlfn.CONCAT("Data[", N$10, "]"))>0, INDIRECT(_xlfn.CONCAT("Data[", N$10, "]"))))))} -> 3.5 | P14: =Rankings!$M$1 -> samuelbattista | Q14: =COUNTIFS(Data[Date],">"&TODAY()-$T$9,Data[Poster],$P14,INDIRECT(_xlfn.CONCAT("Data[", Q$10, "]")),$P$9) -> 9 | R14: =COUNTIFS(Data[Date],">"&TODAY()-$T$9,Data[Poster],$P14,INDIRECT(_xlfn.CONCAT("Data[", R$10, "]")),$P$9) -> 60 | S14: =COUNTIFS(Data[Date],">"&TODAY()-$T$9,Data[Poster],$P14,INDIRECT(_xlfn.CONCAT("Data[", S$10, "]")),$P$9) -> 75 | T14: =COUNTIFS(Data[Date],">"&TODAY()-$T$9,Data[Poster],$P14,INDIRECT(_xlfn.CONCAT("Data[", T$10, "]")),$P$9) -> 361 | U14: =COUNTIFS(Data[Date],">"&TODAY()-$T$9,Data[Poster],$P14,INDIRECT(_xlfn.CONCAT("Data[", U$10, "]")),$P$9) -> 15 | V14: =SUM(Q14:U14) -> 520 | X14: =Rankings!$M$1 -> samuelbattista | Y14: =COUNTIFS(Data[Date],">"&TODAY()-$AB$9,Data[Poster],$X14,INDIRECT(_xlfn.CONCAT("Data[", Y$10, "]")),$X$9) -> 87 | Z14: =COUNTIFS(Data[Date],">"&TODAY()-$AB$9,Data[Poster],$X14,INDIRECT(_xlfn.CONCAT("Data[", Z$10, "]")),$X$9) -> 97 | AA14: =COUNTIFS(Data[Date],">"&TODAY()-$AB$9,Data[Poster],$X14,INDIRECT(_xlfn.CONCAT("Data[", AA$10, "]")),$X$9) -> 87 | AB14: =COUNTIFS(Data[Date],">"&TODAY()-$AB$9,Data[Poster],$X14,INDIRECT(_xlfn.CONCAT("Data[", AB$10, "]")),$X$9) -> 59 | AC14: =COUNTIFS(Data[Date],">"&TODAY()-$AB$9,Data[Poster],$X14,INDIRECT(_xlfn.CONCAT("Data[", AC$10, "]")),$X$9) -> 85 | AD14: =SUM(Y14:AC14) -> 415
B15: =Rankings!$N$1 -> currydestroyer27 | C15: {=AVERAGE(IF(Data[Poster]=$B15, IF(Data[Date]> TODAY()-$E$9, IF(INDIRECT(_xlfn.CONCAT("Data[", C$10, "]"))>0, INDIRECT(_xlfn.CONCAT("Data[", C$10, "]"))))))} -> 3.25 | D15: {=AVERAGE(IF(Data[Poster]=$B15, IF(Data[Date]> TODAY()-$E$9, IF(INDIRECT(_xlfn.CONCAT("Data[", D$10, "]"))>0, INDIRECT(_xlfn.CONCAT("Data[", D$10, "]"))))))} -> 2.875 | E15: {=AVERAGE(IF(Data[Poster]=$B15, IF(Data[Date]> TODAY()-$E$9, IF(INDIRECT(_xlfn.CONCAT("Data[", E$10, "]"))>0, INDIRECT(_xlfn.CONCAT("Data[", E$10, "]"))))))} -> 3.0625 | F15: {=AVERAGE(IF(Data[Poster]=$B15, IF(Data[Date]> TODAY()-$E$9, IF(INDIRECT(_xlfn.CONCAT("Data[", F$10, "]"))>0, INDIRECT(_xlfn.CONCAT("Data[", F$10, "]"))))))} -> 3.6875 | G15: {=AVERAGE(IF(Data[Poster]=$B15, IF(Data[Date]> TODAY()-$E$9, IF(INDIRECT(_xlfn.CONCAT("Data[", G$10, "]"))>0, INDIRECT(_xlfn.CONCAT("Data[", G$10, "]"))))))} -> 1.625 | I15: =Rankings!$N$1 -> currydestroyer27 | J15: {=MEDIAN(IF(Data[Poster]=$I15, IF(Data[Date]> TODAY()-$L$9, IF(INDIRECT(_xlfn.CONCAT("Data[", J$10, "]"))>0, INDIRECT(_xlfn.CONCAT("Data[", J$10, "]"))))))} -> 3 | K15: {=MEDIAN(IF(Data[Poster]=$I15, IF(Data[Date]> TODAY()-$L$9, IF(INDIRECT(_xlfn.CONCAT("Data[", K$10, "]"))>0, INDIRECT(_xlfn.CONCAT("Data[", K$10, "]"))))))} -> 3 | L15: {=MEDIAN(IF(Data[Poster]=$I15, IF(Data[Date]> TODAY()-$L$9, IF(INDIRECT(_xlfn.CONCAT("Data[", L$10, "]"))>0, INDIRECT(_xlfn.CONCAT("Data[", L$10, "]"))))))} -> 3 | M15: {=MEDIAN(IF(Data[Poster]=$I15, IF(Data[Date]> TODAY()-$L$9, IF(INDIRECT(_xlfn.CONCAT("Data[", M$10, "]"))>0, INDIRECT(_xlfn.CONCAT("Data[", M$10, "]"))))))} -> 4 | N15: {=MEDIAN(IF(Data[Poster]=$I15, IF(Data[Date]> TODAY()-$L$9, IF(INDIRECT(_xlfn.CONCAT("Data[", N$10, "]"))>0, INDIRECT(_xlfn.CONCAT("Data[", N$10, "]"))))))} -> 1 | P15: =Rankings!$N$1 -> currydestroyer27 | Q15: =COUNTIFS(Data[Date],">"&TODAY()-$T$9,Data[Poster],$P15,INDIRECT(_xlfn.CONCAT("Data[", Q$10, "]")),$P$9) -> 18 | R15: =COUNTIFS(Data[Date],">"&TODAY()-$T$9,Data[Poster],$P15,INDIRECT(_xlfn.CONCAT("Data[", R$10, "]")),$P$9) -> 57 | S15: =COUNTIFS(Data[Date],">"&TODAY()-$T$9,Data[Poster],$P15,INDIRECT(_xlfn.CONCAT("Data[", S$10, "]")),$P$9) -> 65 | T15: =COUNTIFS(Data[Date],">"&TODAY()-$T$9,Data[Poster],$P15,INDIRECT(_xlfn.CONCAT("Data[", T$10, "]")),$P$9) -> 19 | U15: =COUNTIFS(Data[Date],">"&TODAY()-$T$9,Data[Poster],$P15,INDIRECT(_xlfn.CONCAT("Data[", U$10, "]")),$P$9) -> 335 | V15: =SUM(Q15:U15) -> 494 | X15: =Rankings!$N$1 -> currydestroyer27 | Y15: =COUNTIFS(Data[Date],">"&TODAY()-$AB$9,Data[Poster],$X15,INDIRECT(_xlfn.CONCAT("Data[", Y$10, "]")),$X$9) -> 120 | Z15: =COUNTIFS(Data[Date],">"&TODAY()-$AB$9,Data[Poster],$X15,INDIRECT(_xlfn.CONCAT("Data[", Z$10, "]")),$X$9) -> 103 | AA15: =COUNTIFS(Data[Date],">"&TODAY()-$AB$9,Data[Poster],$X15,INDIRECT(_xlfn.CONCAT("Data[", AA$10, "]")),$X$9) -> 106 | AB15: =COUNTIFS(Data[Date],">"&TODAY()-$AB$9,Data[Poster],$X15,INDIRECT(_xlfn.CONCAT("Data[", AB$10, "]")),$X$9) -> 84 | AC15: =COUNTIFS(Data[Date],">"&TODAY()-$AB$9,Data[Poster],$X15,INDIRECT(_xlfn.CONCAT("Data[", AC$10, "]")),$X$9) -> 62 | AD15: =SUM(Y15:AC15) -> 475
B17: Standard Deviation for past | E17: 28 | F17: days | I17: Mode Rank for past | L17: 28 | M17: days | P17: 3 | Q17: =_xlfn.CONCAT("Amount of ",P17,"'s given for past") -> Amount of 3's given for past | T17: 1000 | U17: days | V17: Sum | X17: 4 | Y17: =_xlfn.CONCAT("Amount of ",X17,"'s given for past") -> Amount of 4's given for past | AB17: 1000 | AC17: days | AD17: Sum
B18: Poster\Voter | C18: =Rankings!$J$1 -> alappatjoe | D18: =Rankings!$K$1 -> danram | E18: =Rankings!$L$1 -> loganworsdell | F18: =Rankings!$M$1 -> samuelbattista | G18: =Rankings!$N$1 -> currydestroyer27 | I18: Poster\Voter | J18: =Rankings!$J$1 -> alappatjoe | K18: =Rankings!$K$1 -> danram | L18: =Rankings!$L$1 -> loganworsdell | M18: =Rankings!$M$1 -> samuelbattista | N18: =Rankings!$N$1 -> currydestroyer27 | P18: Poster\Voter | Q18: =Rankings!$J$1 -> alappatjoe | R18: =Rankings!$K$1 -> danram | S18: =Rankings!$L$1 -> loganworsdell | T18: =Rankings!$M$1 -> samuelbattista | U18: =Rankings!$N$1 -> currydestroyer27 | X18: Poster\Voter | Y18: =Rankings!$J$1 -> alappatjoe | Z18: =Rankings!$K$1 -> danram | AA18: =Rankings!$L$1 -> loganworsdell | AB18: =Rankings!$M$1 -> samuelbattista | AC18: =Rankings!$N$1 -> currydestroyer27
